Workbook
Name Slicer_Month: #N/A

Sheet DASHBOARD

Sheet Processing
A1: Month | B1: X | C1: Indent | D1: Income | E1: Expenses | F1: Indent C | G1: Cursor I | H1: Cursor E | I1: Marker | J1: Lable | K1: Month N | L1: Ratio | M1: Ratio Income | O1: X | P1: Y
A2: JANUARY | B2: =LEFT(A2,3) -> JAN | C2: =$C$14 -> 1449.24 | D2: =GETPIVOTDATA(""&D$1,Control!$A$16,"Month",""&A2) -> 18166 | E2: =GETPIVOTDATA(""&E$1,Control!$A$16,"Month",""&A6) -> 24519 | F2: =C2 -> 1449.24 | G2: =IFERROR(GETPIVOTDATA(""&D$1,Control!$A$3,"Month",""&$A2),NA()) -> #N/A | H2: =IFERROR(GETPIVOTDATA(""&E$1,Control!$A$3,"Month",""&$A2),NA()) -> #N/A | I2: =C2+G2 -> #N/A | J2: =IF(G2>=1000,TEXT(ROUND(G2/1000,0),"0k"),G2) -> #N/A | K2: =GETPIVOTDATA("Max of Month N",Control!$A$1) -> 10 | L2: =D2/SUM(D2:E2) -> 0.42558276 | M2: =INDEX(L2:L13,K2) -> 0.62016267 | N2: =1-M2 -> 0.37983733 | O2: 0 | P2: 1
A3: FEBRUARY | B3: =LEFT(A3,3) -> FEB | C3: =$C$14 -> 1449.24 | D3: =GETPIVOTDATA(""&D$1,Control!$A$16,"Month",""&A3) -> 19801 | E3: =GETPIVOTDATA(""&E$1,Control!$A$16,"Month",""&A7) -> 24837 | F3: =C3 -> 1449.24 | G3: =IFERROR(GETPIVOTDATA(""&D$1,Control!$A$3,"Month",""&$A3),NA()) -> #N/A | H3: =IFERROR(GETPIVOTDATA(""&E$1,Control!$A$3,"Month",""&$A3),NA()) -> #N/A | I3: =C3+G3 -> #N/A | J3: =IF(G3>=1000,TEXT(ROUND(G3/1000,0),"0k"),G3) -> #N/A | L3: =D3/SUM(D3:E3) -> 0.44359066 | O3: =SIN(M2*2*PI()) -> -0.68529181 | P3: =COS(N2*2*PI()) -> -0.72826859
A4: MARCH | B4: =LEFT(A4,3) -> MAR | C4: =$C$14 -> 1449.24 | D4: =GETPIVOTDATA(""&D$1,Control!$A$16,"Month",""&A4) -> 22196 | E4: =GETPIVOTDATA(""&E$1,Control!$A$16,"Month",""&A8) -> 21183 | F4: =C4 -> 1449.24 | G4: =IFERROR(GETPIVOTDATA(""&D$1,Control!$A$3,"Month",""&$A4),NA()) -> 22196 | H4: =IFERROR(GETPIVOTDATA(""&E$1,Control!$A$3,"Month",""&$A4),NA()) -> 22099 | I4: =C4+G4 -> 23645.24 | J4: =IF(G4>=1000,TEXT(ROUND(G4/1000,0),"0k"),G4) -> 22k | L4: =D4/SUM(D4:E4) -> 0.51167616
A5: APRIL | B5: =LEFT(A5,3) -> APR | C5: =$C$14 -> 1449.24 | D5: =GETPIVOTDATA(""&D$1,Control!$A$16,"Month",""&A5) -> 25558 | E5: =GETPIVOTDATA(""&E$1,Control!$A$16,"Month",""&A9) -> 22263 | F5: =C5 -> 1449.24 | G5: =IFERROR(GETPIVOTDATA(""&D$1,Control!$A$3,"Month",""&$A5),NA()) -> 25558 | H5: =IFERROR(GETPIVOTDATA(""&E$1,Control!$A$3,"Month",""&$A5),NA()) -> 19614 | I5: =C5+G5 -> 27007.24 | J5: =IF(G5>=1000,TEXT(ROUND(G5/1000,0),"0k"),G5) -> 26k | K5: Balance | L5: =D5/SUM(D5:E5) -> 0.53445139
A6: MAY | B6: =LEFT(A6,3) -> MAY | C6: =$C$14 -> 1449.24 | D6: =GETPIVOTDATA(""&D$1,Control!$A$16,"Month",""&A6) -> 31043 | E6: =GETPIVOTDATA(""&E$1,Control!$A$16,"Month",""&A10) -> 25507 | F6: =C6 -> 1449.24 | G6: =IFERROR(GETPIVOTDATA(""&D$1,Control!$A$3,"Month",""&$A6),NA()) -> 31043 | H6: =IFERROR(GETPIVOTDATA(""&E$1,Control!$A$3,"Month",""&$A6),NA()) -> 24519 | I6: =C6+G6 -> 32492.24 | J6: =IF(G6>=1000,TEXT(ROUND(G6/1000,0),"0k"),G6) -> 31k | K6: =GETPIVOTDATA("Average of Balance",Control!$A$1) -> 4465.3265 | L6: =D6/SUM(D6:E6) -> 0.54894783
A7: JUNE | B7: =LEFT(A7,3) -> JUN | C7: =$C$14 -> 1449.24 | D7: =GETPIVOTDATA(""&D$1,Control!$A$16,"Month",""&A7) -> 31211 | E7: =GETPIVOTDATA(""&E$1,Control!$A$16,"Month",""&A11) -> 20455 | F7: =C7 -> 1449.24 | G7: =IFERROR(GETPIVOTDATA(""&D$1,Control!$A$3,"Month",""&$A7),NA()) -> 31211 | H7: =IFERROR(GETPIVOTDATA(""&E$1,Control!$A$3,"Month",""&$A7),NA()) -> 24837 | I7: =C7+G7 -> 32660.24 | J7: =IF(G7>=1000,TEXT(ROUND(G7/1000,0),"0k"),G7) -> 31k | L7: =D7/SUM(D7:E7) -> 0.60409167
A8: JULY | B8: =LEFT(A8,3) -> JUL | C8: =$C$14 -> 1449.24 | D8: =GETPIVOTDATA(""&D$1,Control!$A$16,"Month",""&A8) -> 30268 | E8: =GETPIVOTDATA(""&E$1,Control!$A$16,"Month",""&A12) -> 26772 | F8: =C8 -> 1449.24 | G8: =IFERROR(GETPIVOTDATA(""&D$1,Control!$A$3,"Month",""&$A8),NA()) -> 30268 | H8: =IFERROR(GETPIVOTDATA(""&E$1,Control!$A$3,"Month",""&$A8),NA()) -> 21183 | I8: =C8+G8 -> 31717.24 | J8: =IF(G8>=1000,TEXT(ROUND(G8/1000,0),"0k"),G8) -> 30k | L8: =D8/SUM(D8:E8) -> 0.53064516
A9: AUGUST | B9: =LEFT(A9,3) -> AUG | C9: =$C$14 -> 1449.24 | D9: =GETPIVOTDATA(""&D$1,Control!$A$16,"Month",""&A9) -> 35419 | E9: =GETPIVOTDATA(""&E$1,Control!$A$16,"Month",""&A13) -> 24419 | F9: =C9 -> 1449.24 | G9: =IFERROR(GETPIVOTDATA(""&D$1,Control!$A$3,"Month",""&$A9),NA()) -> 35419 | H9: =IFERROR(GETPIVOTDATA(""&E$1,Control!$A$3,"Month",""&$A9),NA()) -> 22263 | I9: =C9+G9 -> 36868.24 | J9: =IF(G9>=1000,TEXT(ROUND(G9/1000,0),"0k"),G9) -> 35k | L9: =D9/SUM(D9:E9) -> 0.59191484
A10: SEPTEMBER | B10: =LEFT(A10,3) -> SEP | C10: =$C$14 -> 1449.24 | D10: =GETPIVOTDATA(""&D$1,Control!$A$16,"Month",""&A10) -> 35296 | E10: =GETPIVOTDATA(""&E$1,Control!$A$16,"Month",""&A10) -> 25507 | F10: =C10 -> 1449.24 | G10: =IFERROR(GETPIVOTDATA(""&D$1,Control!$A$3,"Month",""&$A10),NA()) -> 35296 | H10: =IFERROR(GETPIVOTDATA(""&E$1,Control!$A$3,"Month",""&$A10),NA()) -> 25507 | I10: =C10+G10 -> 36745.24 | J10: =IF(G10>=1000,TEXT(ROUND(G10/1000,0),"0k"),G10) -> 35k | L10: =D10/SUM(D10:E10) -> 0.58049767
A11: OCTOBER | B11: =LEFT(A11,3) -> OCT | C11: =$C$14 -> 1449.24 | D11: =GETPIVOTDATA(""&D$1,Control!$A$16,"Month",""&A11) -> 33397 | E11: =GETPIVOTDATA(""&E$1,Control!$A$16,"Month",""&A11) -> 20455 | F11: =C11 -> 1449.24 | G11: =IFERROR(GETPIVOTDATA(""&D$1,Control!$A$3,"Month",""&$A11),NA()) -> 33397 | H11: =IFERROR(GETPIVOTDATA(""&E$1,Control!$A$3,"Month",""&$A11),NA()) -> 20455 | I11: =C11+G11 -> 34846.24 | J11: =IF(G11>=1000,TEXT(ROUND(G11/1000,0),"0k"),G11) -> 33k | L11: =D11/SUM(D11:E11) -> 0.62016267
A12: NOVEMBER | B12: =LEFT(A12,3) -> NOV | C12: =$C$14 -> 1449.24 | D12: =GETPIVOTDATA(""&D$1,Control!$A$16,"Month",""&A12) -> 33613 | E12: =GETPIVOTDATA(""&E$1,Control!$A$16,"Month",""&A12) -> 26772 | F12: =C12 -> 1449.24 | G12: =IFERROR(GETPIVOTDATA(""&D$1,Control!$A$3,"Month",""&$A12),NA()) -> #N/A | H12: =IFERROR(GETPIVOTDATA(""&E$1,Control!$A$3,"Month",""&$A12),NA()) -> #N/A | I12: =C12+G12 -> #N/A | J12: =IF(G12>=1000,TEXT(ROUND(G12/1000,0),"0k"),G12) -> #N/A | L12: =D12/SUM(D12:E12) -> 0.55664486
A13: DECEMBER | B13: =LEFT(A13,3) -> DEC | C13: =$C$14 -> 1449.24 | D13: =GETPIVOTDATA(""&D$1,Control!$A$16,"Month",""&A13) -> 36231 | E13: =GETPIVOTDATA(""&E$1,Control!$A$16,"Month",""&A13) -> 24419 | F13: =C13 -> 1449.24 | G13: =IFERROR(GETPIVOTDATA(""&D$1,Control!$A$3,"Month",""&$A13),NA()) -> #N/A | H13: =IFERROR(GETPIVOTDATA(""&E$1,Control!$A$3,"Month",""&$A13),NA()) -> #N/A | I13: =C13+G13 -> #N/A | J13: =IF(G13>=1000,TEXT(ROUND(G13/1000,0),"0k"),G13) -> #N/A | L13: =D13/SUM(D13:E13) -> 0.5973784
C14: =MAX(D2:E13)*4% -> 1449.24 | D14: =GETPIVOTDATA("Sum of Income",Control!$A$1) -> 244388 | E14: =GETPIVOTDATA("Sum of Expenses",Control!$A$1) -> 180477
A16: Budget | B16: =B17-A27 -> 64083
A17: Budget Plan | B17: 300000 | E17: Budgeting | N17: Debts | O17: Interest Rate
A18: Non-Fixed Incom | B18: =GETPIVOTDATA(""&A18,Control!$A$1) -> 86966 | C18: =B18/SUM(B24:B25) -> 0.2046909 | E18: =TRANSPOSE(C18) -> 0.2046909 | F18: =TRANSPOSE(C19) -> 0.66418146 | G18: =TRANSPOSE(C20) -> 0.088385723 | H18: =TRANSPOSE(C21) -> 0.15312393 | I18: =TRANSPOSE(C22) -> 0.21105292 | J18: =TRANSPOSE(C23) -> 0.060609841 | N18: Mortgage | O18: 0.03 | P18: =GETPIVOTDATA(""&N18,Control!$A$1) -> 28842.857
A19: Fixed Incom | B19: =GETPIVOTDATA(""&A19,Control!$A$1) -> 119870 | C19: =B19/SUM(B25:B26) -> 0.66418146 | E19: =E18 -> 0.2046909 | F19: =F18 -> 0.66418146 | G19: =G18 -> 0.088385723 | H19: =H18 -> 0.15312393 | I19: =I18 -> 0.21105292 | J19: =J18 -> 0.060609841 | N19: Car Leasing | O19: 0.1 | P19: =GETPIVOTDATA(""&N19,Control!$A$1) -> 12336.735
A20: Other Income | B20: =GETPIVOTDATA(""&A20,Control!$A$1) -> 37552 | C20: =B20/SUM(B24:B25) -> 0.088385723 | E20: =E19 -> 0.2046909 | F20: =F19 -> 0.66418146 | G20: =G19 -> 0.088385723 | H20: =H19 -> 0.15312393 | I20: =I19 -> 0.21105292 | J20: =J19 -> 0.060609841 | N20: Consumer Credit | O20: 0.05 | P20: =GETPIVOTDATA(""&N20,Control!$A$1) -> 8681.4408
A21: Non-Fixed Cost | B21: =GETPIVOTDATA(""&A21,Control!$A$1) -> 65057 | C21: =B21/SUM(B24:B25) -> 0.15312393 | N21: Credit Card | O21: 0.07 | P21: =GETPIVOTDATA(""&N21,Control!$A$1) -> 18122.673
A22: Fixed Costs | B22: =GETPIVOTDATA(""&A22,Control!$A$1) -> 89669 | C22: =B22/SUM(B24:B25) -> 0.21105292 | E22: Investments | F22: Invest | G22: =SUM(F23:F27) -> 103614.83 | L22: Labels | P22: =SUM(P18:P21) -> 67983.706
A23: Other Cost | B23: =GETPIVOTDATA(""&A23,Control!$A$1) -> 25751 | C23: =B23/SUM(B24:B25) -> 0.060609841 | E23: Investments Business | F23: =GETPIVOTDATA(""&E23,Control!$A$1) -> 31085.597 | G23: =F23/G22 -> 0.30001107 | H23: =G23 -> 0.30001107 | I23: =H23 -> 0.30001107 | J23: =I23 -> 0.30001107 | K23: =J23 -> 0.30001107 | L23: Business
A24: Total Income | B24: =B18+B19+B20 -> 244388 | E24: Investments Securities | F24: =GETPIVOTDATA(""&E24,Control!$A$1) -> 19526.087 | G24: =F24/G22 -> 0.18844876 | H24: =G24 -> 0.18844876 | I24: =H24 -> 0.18844876 | J24: =I24 -> 0.18844876 | K24: =J24 -> 0.18844876 | L24: Securities
A25: Total Costs | B25: =B21+B22+B23 -> 180477 | E25: Investments Cryptocurrency | F25: =GETPIVOTDATA(""&E25,Control!$A$1) -> 17897.979 | G25: =F25/G22 -> 0.17273569 | H25: =G25 -> 0.17273569 | I25: =H25 -> 0.17273569 | J25: =I25 -> 0.17273569 | K25: =J25 -> 0.17273569 | L25: Crypto
A26: Used Budget | B26: =SUM(E2:INDEX(E2:E13,K2))/B17 -> 0.78639 | C26: =1-B26 -> 0.21361 | E26: Investments Real estate | F26: =GETPIVOTDATA(""&E26,Control!$A$1) -> 16561.59 | G26: =F26/G22 -> 0.15983803 | H26: =G26 -> 0.15983803 | I26: =H26 -> 0.15983803 | J26: =I26 -> 0.15983803 | K26: =J26 -> 0.15983803 | L26: Rent
A27: =B17*B26 -> 235917 | E27: Investments Gold | F27: =GETPIVOTDATA(""&E27,Control!$A$1) -> 18543.579 | G27: =F27/G22 -> 0.17896645 | H27: =G27 -> 0.17896645 | I27: =H27 -> 0.17896645 | J27: =I27 -> 0.17896645 | K27: =J27 -> 0.17896645 | L27: Gold
G28: 1 | H28: 1 | I28: 1 | J28: 1 | K28: 1
A30: Implementation | B30: Goal 1 | C30: Goal 2 | D30: Goal 3 | E30: Goal 4 | F30: Total
A31: Done | B31: =GETPIVOTDATA(""&B30,Control!$A$1) -> 47748.547 | C31: =GETPIVOTDATA(""&C30,Control!$A$1) -> 29041.216 | D31: =GETPIVOTDATA(""&D30,Control!$A$1) -> 21960.6 | E31: =GETPIVOTDATA(""&E30,Control!$A$1) -> 13628.91 | F31: =SUM(B31:E31) -> 112379.27
A32: Left | B32: =B33-B31 -> 29251.453 | C32: =C33-C31 -> 35958.784 | D32: =D33-D31 -> 36039.4 | E32: =E33-E31 -> 16371.09 | F32: =SUM(B32:E32) -> 117620.73
A33: Plan | B33: 77000 | C33: 65000 | D33: 58000 | E33: 30000 | F33: =SUM(B33:E33) -> 230000
A34: Done % | B34: =B31/B33 -> 0.620111 | C34: =C31/C33 -> 0.44678794 | D34: =D31/D33 -> 0.37863103 | E34: =E31/E33 -> 0.45429701 | F34: =F31/F33 -> 0.48860554
A35: Goals % | B35: =B33/B36 -> 1 | C35: =C33/B36 -> 0.84415584 | D35: =D33/B36 -> 0.75324675 | E35: =E33/B36 -> 0.38961039 | F35: =1-F34 -> 0.51139446
A36: MAX Plan | B36: =MAX(B33:E33) -> 77000
B38: Goal 4 | D38: Goal 3 | F38: Goal 2 | H38: Goal 1 | I38: Sectors
A39: Done | B39: =(100%-SUM(B41:B42))*INDEX(B34:E34,1,B43) -> 0.13274913 | C39: =(100%-SUM(C41:C42))*INDEX(B34:E34,1,C43) -> 0.13274913 | D39: =(100%-SUM(D41:D42))*INDEX(B34:E34,1,D43) -> 0.21390195 | E39: =(100%-SUM(E41:E42))*INDEX(B34:E34,1,E43) -> 0.21390195 | F39: =(100%-SUM(F41:F42))*INDEX(B34:E34,1,F43) -> 0.28286899 | G39: =(100%-SUM(G41:G42))*INDEX(B34:E34,1,G43) -> 0.28286899 | H39: =(100%-SUM(H41:H42))*INDEX(B34:E34,1,H43) -> 0.46508325 | I39: 0.75
A40: Running | B40: =100%-SUM(B41:B42)-B39 -> 0.15945867 | C40: =100%-SUM(C41:C42)-C39 -> 0.15945867 | D40: =100%-SUM(D41:D42)-D39 -> 0.35103312 | E40: =100%-SUM(E41:E42)-E39 -> 0.35103312 | F40: =100%-SUM(F41:F42)-F39 -> 0.35024789 | G40: =100%-SUM(G41:G42)-G39 -> 0.35024789 | H40: =100%-SUM(H41:H42)-H39 -> 0.28491675 | I40: 0
A41: Level Goal | B41: =(100%-INDEX(B35:E35,1,B43))*I39 -> 0.45779221 | C41: =(100%-INDEX(B35:E35,1,C43))*I39 -> 0.45779221 | D41: =(100%-INDEX(B35:E35,1,D43))*I39 -> 0.18506494 | E41: =(100%-INDEX(B35:E35,1,E43))*I39 -> 0.18506494 | F41: =(100%-INDEX(B35:E35,1,F43))*I39 -> 0.11688312 | G41: =(100%-INDEX(B35:E35,1,G43))*I39 -> 0.11688312 | H41: =(100%-INDEX(B35:E35,1,H43))*I39 -> 0 | I41: 0
A42: Financial Goal | B42: =I42 -> 0.25 | C42: =I42 -> 0.25 | D42: =I42 -> 0.25 | E42: =I42 -> 0.25 | F42: =I42 -> 0.25 | G42: =I42 -> 0.25 | H42: =I42 -> 0.25 | I42: 0.25
B43: 4 | C43: 4 | D43: 3 | E43: 3 | F43: 2 | G43: 2 | H43: 1

Sheet Control
A1: Row Labels | B1: Max of Month N | C1: Sum of Income | D1: Average of Balance | E1: Sum of Expenses | F1: Sum of Non-Fixed Incom | G1: Sum of Fixed Incom | H1: Sum of Other Income | I1: Sum of Non-Fixed Cost | J1: Sum of Fixed Costs | K1: Sum of Other Cost | L1: Average of Investments Business | M1: Average of Investments Securities | N1: Average of Investments Cryptocurrency | O1: Average of Investments Real estate | P1: Average of Investments Gold | Q1: Average of Mortgage | R1: Average of Car Leasing | S1: Average of Consumer Credit | T1: Average of Credit Card | U1: Average of Goal 1 | V1: Average of Goal 2 | W1: Average of Goal 3 | X1: Average of Goal 4
A2: MARCH | B2: 3 | C2: 22196 | D2: 4874.7419 | E2: 22099 | F2: 7857 | G2: 11024 | H2: 3315 | I2: 8658 | J2: 10469 | K2: 2972 | L2: 37933.063 | M2: 22967.65 | N2: 21537.713 | O2: 19901.928 | P2: 24838.401 | Q2: 41080.645 | R2: 14354.839 | S2: 8967.129 | T2: 21415.065 | U2: 30623 | V2: 8722 | W2: 6172 | X2: 2143
A3: APRIL | B3: 4 | C3: 25558 | D3: 4806.6667 | E3: 19614 | F3: 9817 | G3: 11804 | H3: 3937 | I3: 6727 | J3: 10377 | K3: 2510 | L3: 28170.174 | M3: 18431.367 | N3: 17129.157 | O3: 14639.856 | P3: 14968.85 | Q3: 37633.333 | R3: 14791.667 | S3: 10260.8 | T3: 21284.6 | U3: 35764 | V3: 13723 | W3: 8643 | X3: 5764
A4: MAY | B4: 5 | C4: 31043 | D4: 4125.9032 | E4: 24519 | F4: 10953 | G4: 15158 | H4: 4932 | I4: 9137 | J4: 11921 | K4: 3461 | L4: 26294.359 | M4: 17321.329 | N4: 15817.025 | O4: 13975.721 | P4: 15784.787 | Q4: 34080.645 | R4: 15000 | S4: 11477.097 | T4: 21792.097 | U4: 41565 | V4: 18624 | W4: 12724 | X4: 9545
A5: JUNE | B5: 6 | C5: 31211 | D5: 4497.9667 | E5: 24837 | F5: 11590 | G5: 15003 | H5: 4618 | I5: 9032 | J5: 12075 | K5: 3730 | L5: 31848.221 | M5: 20281.183 | N5: 18021.428 | O5: 16422.948 | P5: 19640.418 | Q5: 30633.333 | R5: 12875 | S5: 8324.3 | T5: 19086.467 | U5: 48286 | V5: 22765 | W5: 21425 | X5: 11977
A6: JULY | B6: 7 | C6: 30268 | D6: 4569.8065 | E6: 21183 | F6: 10675 | G6: 14573 | H6: 5020 | I6: 7342 | J6: 10596 | K6: 3245 | L6: 25897.294 | M6: 16191.413 | N6: 15279.437 | O6: 13726.175 | P6: 14619.659 | Q6: 27080.645 | R6: 11693.548 | S6: 7517.6129 | T6: 16256.258 | U6: 49237 | V6: 30576 | W6: 23946 | X6: 13866
A7: AUGUST | B7: 8 | C7: 35419 | D7: 4312.5161 | E7: 22263 | F7: 11695 | G7: 18781 | H7: 4943 | I7: 8546 | J7: 10831 | K7: 2886 | L7: 29516.518 | M7: 19705.899 | N7: 15960.212 | O7: 15341.459 | P7: 18038.058 | Q7: 23580.645 | R7: 11250 | S7: 8178.8387 | T7: 17385.097 | U7: 51528 | V7: 40447 | W7: 28127 | X7: 18319
A8: SEPTEMBER | B8: 9 | C8: 35296 | D8: 4022.3 | E8: 25507 | F8: 11859 | G8: 17735 | H8: 5702 | I8: 8852 | J8: 12996 | K8: 3659 | L8: 36384.663 | M8: 21206.626 | N8: 20620.795 | O8: 19382.437 | P8: 21802.003 | Q8: 20133.333 | R8: 10000 | S8: 7571.8333 | T8: 13266.533 | U8: 60889 | V8: 47668 | W8: 34859 | X8: 23168
A9: OCTOBER | B9: 10 | C9: 33397 | D9: 4510.4839 | E9: 20455 | F9: 12520 | G9: 15792 | H9: 5085 | I9: 6763 | J9: 10404 | K9: 3288 | L9: 32741.977 | M9: 20146.485 | N9: 18885.081 | O9: 19126.729 | P9: 18681.636 | Q9: 16580.645 | R9: 8750 | S9: 7157.5484 | T9: 14471.71 | U9: 64151 | V9: 49709 | W9: 39758 | X9: 24250
A10: Grand Total | B10: 10 | C10: 244388 | D10: 4465.3265 | E10: 180477 | F10: 86966 | G10: 119870 | H10: 37552 | I10: 65057 | J10: 89669 | K10: 25751 | L10: 31085.597 | M10: 19526.087 | N10: 17897.979 | O10: 16561.59 | P10: 18543.579 | Q10: 28842.857 | R10: 12336.735 | S10: 8681.4408 | T10: 18122.673 | U10: 47748.547 | V10: 29041.216 | W10: 21960.6 | X10: 13628.91
A16: Row Labels | B16: Sum of Income | C16: Sum of Expenses
A17: JANUARY | B17: 18166 | C17: 20397
A18: FEBRUARY | B18: 19801 | C18: 26548
A19: MARCH | B19: 22196 | C19: 22099
A20: APRIL | B20: 25558 | C20: 19614
A21: MAY | B21: 31043 | C21: 24519
A22: JUNE | B22: 31211 | C22: 24837
A23: JULY | B23: 30268 | C23: 21183
A24: AUGUST | B24: 35419 | C24: 22263
A25: SEPTEMBER | B25: 35296 | C25: 25507
A26: OCTOBER | B26: 33397 | C26: 20455
A27: NOVEMBER | B27: 33613 | C27: 26772
A28: DECEMBER | B28: 36231 | C28: 24419
A29: Grand Total | B29: 352199 | C29: 278613

Sheet Data
A1: Date | B1: Month | C1: Month N | D1: Income | E1: Expenses | F1: Non-Fixed Incom | G1: Fixed Incom | H1: Other Income | I1: Non-Fixed Cost | J1: Fixed Costs | K1: Other Cost | L1: Fixed Incom Business | M1: Fixed Incom Securities | N1: Fixed Incom Real estate | O1: Fixed Incom Gold | P1: Fixed Incom Cryptocurrency | Q1: Non-Fixed Incom Business | R1: Non-Fixed Incom Securities | S1: Non-Fixed Incom Real estate | T1: Non-Fixed Incom Gold | U1: Non-Fixed Incom Cryptocurrency | V1: Loans | W1: Training courses | X1: Travel public transport | Y1: Mobile connection | Z1: Food | AA1: Utility Payments | AB1: Internet & TV | AC1: Household chemicals | AD1: Furniture & utensils | AE1: BedLinen & tablecloth | AF1: Cat food | AG1: Clothing & footwear | AH1: Gym | AI1: Hygiene products | AJ1: Medications | AK1: Hairdresser | AL1: Cosmetics & perfum | AM1: Fuel | AN1: Spare parts | AO1: Parking | AP1: Washing | AQ1: Insurance | AR1: Holidays | AS1: Excursions | AT1: Restaurants | AU1: Hotels | AV1: Bags, packages, boxes | AW1: Snacks on the way | AX1: Alcohol | AY1: Hobby | AZ1: Unexpected expenses | BA1: Price Investments Portfolio | BB1: Investments Business | BC1: Investments Securities | BD1: Investments Cryptocurrency | BE1: Investments Real estate | BF1: Investments Gold | BG1: Mortgage | BH1: Car Leasing | BI1: Consumer Credit | BJ1: Credit Card | BK1: Goal 1 | BL1: Goal 2 | BM1: Goal 3 | BN1: Goal 4 | BO1: Monthly Plan | BP1: Balance
A2: 45292 | B2: =CHOOSE(C2, "JANUARY", "FEBRUARY", "MARCH", "APRIL", "MAY", "JUNE", "JULY", "AUGUST", "SEPTEMBER", "OCTOBER", "NOVEMBER", "DECEMBER") -> JANUARY | C2: =MONTH(Data!$A2) -> 1 | D2: 496 | E2: 575 | F2: 243 | G2: 189 | H2: 64 | I2: 172 | J2: 271 | K2: 132 | L2: 104 | M2: 58 | N2: 27 | O2: 46 | P2: 9 | Q2: 82 | R2: 62 | S2: 22 | T2: 24 | U2: 62 | V2: 46 | W2: 0 | X2: 23 | Y2: 11 | Z2: 34 | AA2: 34 | AB2: 11 | AC2: 5 | AD2: 28 | AE2: 0 | AF2: 0 | AG2: 5 | AH2: 5 | AI2: 17 | AJ2: 17 | AK2: 23 | AL2: 34 | AM2: 11 | AN2: 17 | AO2: 0 | AP2: 0 | AQ2: 17 | AR2: 51 | AS2: 5 | AT2: 17 | AU2: 11 | AV2: 5 | AW2: 17 | AX2: 0 | AY2: 17 | AZ2: 114 | BA2: 0 | BB2: 0 | BC2: 0 | BD2: 0 | BE2: 0 | BF2: 0 | BG2: 50000 | BH2: 20000 | BI2: 8000 | BJ2: 25000 | BK2: 11891 | BL2: 3480 | BM2: 4930 | BN2: 1741 | BO2: 29000 | BP2: 3796
A3: 45293 | B3: =CHOOSE(C3, "JANUARY", "FEBRUARY", "MARCH", "APRIL", "MAY", "JUNE", "JULY", "AUGUST", "SEPTEMBER", "OCTOBER", "NOVEMBER", "DECEMBER") -> JANUARY | C3: =MONTH(Data!$A3) -> 1 | D3: 516 | E3: 585 | F3: 268 | G3: 218 | H3: 30 | I3: 286 | J3: 259 | K3: 40 | L3: 118 | M3: 19 | N3: 38 | O3: 19 | P3: 6 | Q3: 88 | R3: 27 | S3: 19 | T3: 29 | U3: 153 | V3: 76 | W3: 17 | X3: 29 | Y3: 0 | Z3: 46 | AA3: 29 | AB3: 0 | AC3: 17 | AD3: 29 | AE3: 11 | AF3: 5 | AG3: 23 | AH3: 11 | AI3: 0 | AJ3: 0 | AK3: 23 | AL3: 23 | AM3: 5 | AN3: 11 | AO3: 5 | AP3: 17 | AQ3: 17 | AR3: 64 | AS3: 17 | AT3: 40 | AU3: 29 | AV3: 0 | AW3: 23 | AX3: 11 | AY3: 5 | AZ3: 2 | BA3: 0 | BB3: 0 | BC3: 0 | BD3: 0 | BE3: 0 | BF3: 0 | BG3: 50000 | BH3: 20000 | BI3: 8000 | BJ3: 25000 | BK3: 11891 | BL3: 3480 | BM3: 4930 | BN3: 1741 | BO3: 29000 | BP3: 4881
A4: 45294 | B4: =CHOOSE(C4, "JANUARY", "FEBRUARY", "MARCH", "APRIL", "MAY", "JUNE", "JULY", "AUGUST", "SEPTEMBER", "OCTOBER", "NOVEMBER", "DECEMBER") -> JANUARY | C4: =MONTH(Data!$A4) -> 1 | D4: 539 | E4: 610 | F4: 285 | G4: 131 | H4: 123 | I4: 244 | J4: 318 | K4: 48 | L4: 177 | M4: 106 | N4: 23 | O4: 16 | P4: 20 | Q4: 83 | R4: 18 | S4: 28 | T4: 28 | U4: 40 | V4: 61 | W4: 6 | X4: 36 | Y4: 6 | Z4: 61 | AA4: 48 | AB4: 0 | AC4: 18 | AD4: 36 | AE4: 6 | AF4: 6 | AG4: 24 | AH4: 12 | AI4: 12 | AJ4: 12 | AK4: 54 | AL4: 30 | AM4: 30 | AN4: 18 | AO4: 6 | AP4: 6 | AQ4: 24 | AR4: 0 | AS4: 18 | AT4: 14 | AU4: 24 | AV4: 0 | AW4: 30 | AX4: 12 | AY4: 0 | AZ4: 0 | BA4: 0 | BB4: 0 | BC4: 0 | BD4: 0 | BE4: 0 | BF4: 0 | BG4: 50000 | BH4: 20000 | BI4: 8000 | BJ4: 25000 | BK4: 11891 | BL4: 3480 | BM4: 4930 | BN4: 1741 | BO4: 29000 | BP4: 4766
A5: 45295 | B5: =CHOOSE(C5, "JANUARY", "FEBRUARY", "MARCH", "APRIL", "MAY", "JUNE", "JULY", "AUGUST", "SEPTEMBER", "OCTOBER", "NOVEMBER", "DECEMBER") -> JANUARY | C5: =MONTH(Data!$A5) -> 1 | D5: 557 | E5: 641 | F5: 150 | G5: 307 | H5: 100 | I5: 262 | J5: 219 | K5: 160 | L5: 176 | M5: 69 | N5: 31 | O5: 24 | P5: 31 | Q5: 103 | R5: 52 | S5: 27 | T5: 29 | U5: 15 | V5: 44 | W5: 12 | X5: 38 | Y5: 6 | Z5: 44 | AA5: 57 | AB5: 19 | AC5: 0 | AD5: 38 | AE5: 6 | AF5: 0 | AG5: 19 | AH5: 19 | AI5: 19 | AJ5: 0 | AK5: 38 | AL5: 19 | AM5: 32 | AN5: 12 | AO5: 6 | AP5: 12 | AQ5: 6 | AR5: 57 | AS5: 19 | AT5: 25 | AU5: 19 | AV5: 6 | AW5: 19 | AX5: 19 | AY5: 19 | AZ5: 12 | BA5: 0 | BB5: 0 | BC5: 0 | BD5: 0 | BE5: 0 | BF5: 0 | BG5: 50000 | BH5: 20000 | BI5: 8000 | BJ5: 25000 | BK5: 11891 | BL5: 3480 | BM5: 4930 | BN5: 1741 | BO5: 29000 | BP5: 788
A6: 45296 | B6: =CHOOSE(C6, "JANUARY", "FEBRUARY", "MARCH", "APRIL", "MAY", "JUNE", "JULY", "AUGUST", "SEPTEMBER", "OCTOBER", "NOVEMBER", "DECEMBER") -> JANUARY | C6: =MONTH(Data!$A6) -> 1 | D6: 575 | E6: 667 | F6: 132 | G6: 415 | H6: 28 | I6: 153 | J6: 374 | K6: 140 | L6: 171 | M6: 99 | N6: 42 | O6: 35 | P6: 21 | Q6: 93 | R6: 43 | S6: 24 | T6: 21 | U6: 26 | V6: 60 | W6: 0 | X6: 46 | Y6: 20 | Z6: 93 | AA6: 53 | AB6: 20 | AC6: 0 | AD6: 13 | AE6: 20 | AF6: 0 | AG6: 6 | AH6: 13 | AI6: 0 | AJ6: 0 | AK6: 26 | AL6: 46 | AM6: 13 | AN6: 0 | AO6: 0 | AP6: 26 | AQ6: 20 | AR6: 73 | AS6: 6 | AT6: 20 | AU6: 20 | AV6: 0 | AW6: 26 | AX6: 0 | AY6: 20 | AZ6: 27 | BA6: 104.1755 | BB6: 0 | BC6: 0 | BD6: 0 | BE6: 0 | BF6: 0 | BG6: 50000 | BH6: 20000 | BI6: 8000 | BJ6: 23668 | BK6: 11891 | BL6: 3480 | BM6: 4930 | BN6: 1741 | BO6: 29000 | BP6: 4853
A7: 45297 | B7: =CHOOSE(C7, "JANUARY", "FEBRUARY", "MARCH", "APRIL", "MAY", "JUNE", "JULY", "AUGUST", "SEPTEMBER", "OCTOBER", "NOVEMBER", "DECEMBER") -> JANUARY | C7: =MONTH(Data!$A7) -> 1 | D7: 586 | E7: 685 | F7: 175 | G7: 335 | H7: 76 | I7: 212 | J7: 336 | K7: 137 | L7: 134 | M7: 21 | N7: 47 | O7: 29 | P7: 14 | Q7: 120 | R7: 77 | S7: 28 | T7: 11 | U7: 105 | V7: 75 | W7: 6 | X7: 34 | Y7: 13 | Z7: 63 | AA7: 47 | AB7: 20 | AC7: 0 | AD7: 34 | AE7: 6 | AF7: 0 | AG7: 27 | AH7: 0 | AI7: 6 | AJ7: 13 | AK7: 47 | AL7: 47 | AM7: 27 | AN7: 6 | AO7: 0 | AP7: 6 | AQ7: 13 | AR7: 68 | AS7: 13 | AT7: 34 | AU7: 13 | AV7: 6 | AW7: 41 | AX7: 0 | AY7: 20 | AZ7: 0 | BA7: 100.9205 | BB7: 0 | BC7: 0 | BD7: 0 | BE7: 0 | BF7: 0 | BG7: 50000 | BH7: 20000 | BI7: 8000 | BJ7: 23668 | BK7: 11891 | BL7: 3480 | BM7: 4930 | BN7: 1741 | BO7: 29000 | BP7: 3534
A8: 45298 | B8: =CHOOSE(C8, "JANUARY", "FEBRUARY", "MARCH", "APRIL", "MAY", "JUNE", "JULY", "AUGUST", "SEPTEMBER", "OCTOBER", "NOVEMBER", "DECEMBER") -> JANUARY | C8: =MONTH(Data!$A8) -> 1 | D8: 597 | E8: 690 | F8: 310 | G8: 162 | H8: 125 | I8: 282 | J8: 353 | K8: 55 | L8: 166 | M8: 122 | N8: 37 | O8: 22 | P8: 18 | Q8: 77 | R8: 74 | S8: 27 | T8: 34 | U8: 20 | V8: 75 | W8: 0 | X8: 27 | Y8: 6 | Z8: 75 | AA8: 48 | AB8: 6 | AC8: 13 | AD8: 41 | AE8: 20 | AF8: 0 | AG8: 6 | AH8: 20 | AI8: 0 | AJ8: 13 | AK8: 48 | AL8: 6 | AM8: 6 | AN8: 0 | AO8: 0 | AP8: 13 | AQ8: 6 | AR8: 55 | AS8: 6 | AT8: 48 | AU8: 6 | AV8: 6 | AW8: 20 | AX8: 0 | AY8: 0 | AZ8: 120 | BA8: 97.5105 | BB8: 0 | BC8: 0 | BD8: 0 | BE8: 0 | BF8: 0 | BG8: 50000 | BH8: 20000 | BI8: 8000 | BJ8: 23668 | BK8: 11891 | BL8: 3480 | BM8: 4930 | BN8: 1741 | BO8: 29000 | BP8: 7918
A9: 45299 | B9: =CHOOSE(C9, "JANUARY", "FEBRUARY", "MARCH", "APRIL", "MAY", "JUNE", "JULY", "AUGUST", "SEPTEMBER", "OCTOBER", "NOVEMBER", "DECEMBER") -> JANUARY | C9: =MONTH(Data!$A9) -> 1 | D9: 604 | E9: 684 | F9: 217 | G9: 273 | H9: 114 | I9: 307 | J9: 316 | K9: 61 | L9: 149 | M9: 101 | N9: 48 | O9: 37 | P9: 7 | Q9: 126 | R9: 59 | S9: 25 | T9: 11 | U9: 41 | V9: 54 | W9: 13 | X9: 47 | Y9: 13 | Z9: 9 | AA9: 54 | AB9: 13 | AC9: 20 | AD9: 13 | AE9: 13 | AF9: 0 | AG9: 34 | AH9: 20 | AI9: 6 | AJ9: 20 | AK9: 41 | AL9: 34 | AM9: 34 | AN9: 20 | AO9: 6 | AP9: 13 | AQ9: 13 | AR9: 61 | AS9: 13 | AT9: 27 | AU9: 34 | AV9: 6 | AW9: 41 | AX9: 6 | AY9: 6 | AZ9: 0 | BA9: 96.6115 | BB9: 0 | BC9: 0 | BD9: 0 | BE9: 0 | BF9: 0 | BG9: 50000 | BH9: 20000 | BI9: 8000 | BJ9: 23668 | BK9: 11891 | BL9: 3480 | BM9: 4930 | BN9: 1741 | BO9: 29000 | BP9: 520
A10: 45300 | B10: =CHOOSE(C10, "JANUARY", "FEBRUARY", "MARCH", "APRIL", "MAY", "JUNE", "JULY", "AUGUST", "SEPTEMBER", "OCTOBER", "NOVEMBER", "DECEMBER") -> JANUARY | C10: =MONTH(Data!$A10) -> 1 | D10: 606 | E10: 664 | F10: 284 | G10: 262 | H10: 60 | I10: 232 | J10: 346 | K10: 86 | L10: 157 | M10: 127 | N10: 56 | O10: 26 | P10: 33 | Q10: 89 | R10: 64 | S10: 20 | T10: 34 | U10: 0 | V10: 86 | W10: 0 | X10: 19 | Y10: 19 | Z10: 59 | AA10: 59 | AB10: 19 | AC10: 6 | AD10: 39 | AE10: 0 | AF10: 0 | AG10: 19 | AH10: 19 | AI10: 19 | AJ10: 6 | AK10: 46 | AL10: 6 | AM10: 26 | AN10: 0 | AO10: 6 | AP10: 19 | AQ10: 13 | AR10: 66 | AS10: 19 | AT10: 19 | AU10: 13 | AV10: 0 | AW10: 13 | AX10: 19 | AY10: 0 | AZ10: 30 | BA10: 95.7435 | BB10: 0 | BC10: 0 | BD10: 0 | BE10: 0 | BF10: 0 | BG10: 50000 | BH10: 20000 | BI10: 8000 | BJ10: 23668 | BK10: 11891 | BL10: 3480 | BM10: 4930 | BN10: 1741 | BO10: 29000 | BP10: 6207
A11: 45301 | B11: =CHOOSE(C11, "JANUARY", "FEBRUARY", "MARCH", "APRIL", "MAY", "JUNE", "JULY", "AUGUST", "SEPTEMBER", "OCTOBER", "NOVEMBER", "DECEMBER") -> JANUARY | C11: =MONTH(Data!$A11) -> 1 | D11: 602 | E11: 625 | F11: 258 | G11: 314 | H11: 30 | I11: 131 | J11: 451 | K11: 43 | L11: 160 | M11: 97 | N11: 52 | O11: 18 | P11: 14 | Q11: 86 | R11: 16 | S11: 18 | T11: 13 | U11: 128 | V11: 25 | W11: 0 | X11: 43 | Y11: 18 | Z11: 75 | AA11: 56 | AB11: 18 | AC11: 0 | AD11: 12 | AE11: 0 | AF11: 0 | AG11: 6 | AH11: 6 | AI11: 0 | AJ11: 6 | AK11: 43 | AL11: 43 | AM11: 6 | AN11: 12 | AO11: 0 | AP11: 12 | AQ11: 18 | AR11: 62 | AS11: 12 | AT11: 50 | AU11: 31 | AV11: 0 | AW11: 25 | AX11: 0 | AY11: 12 | AZ11: 34 | BA11: 96.3325 | BB11: 0 | BC11: 0 | BD11: 0 | BE11: 0 | BF11: 0 | BG11: 50000 | BH11: 20000 | BI11: 8000 | BJ11: 23668 | BK11: 11891 | BL11: 3480 | BM11: 4930 | BN11: 1741 | BO11: 29000 | BP11: 4999
A12: 45302 | B12: =CHOOSE(C12, "JANUARY", "FEBRUARY", "MARCH", "APRIL", "MAY", "JUNE", "JULY", "AUGUST", "SEPTEMBER", "OCTOBER", "NOVEMBER", "DECEMBER") -> JANUARY | C12: =MONTH(Data!$A12) -> 1 | D12: 584 | E12: 588 | F12: 186 | G12: 334 | H12: 64 | I12: 158 | J12: 313 | K12: 117 | L12: 188 | M12: 86 | N12: 36 | O12: 18 | P12: 18 | Q12: 79 | R12: 17 | S12: 33 | T12: 19 | U12: 90 | V12: 58 | W12: 0 | X12: 35 | Y12: 17 | Z12: 23 | AA12: 35 | AB12: 11 | AC12: 5 | AD12: 17 | AE12: 17 | AF12: 5 | AG12: 17 | AH12: 5 | AI12: 5 | AJ12: 17 | AK12: 52 | AL12: 23 | AM12: 23 | AN12: 11 | AO12: 0 | AP12: 23 | AQ12: 17 | AR12: 41 | AS12: 5 | AT12: 52 | AU12: 11 | AV12: 0 | AW12: 29 | AX12: 17 | AY12: 17 | AZ12: 0 | BA12: 98.6575 | BB12: 0 | BC12: 0 | BD12: 0 | BE12: 0 | BF12: 0 | BG12: 50000 | BH12: 20000 | BI12: 8000 | BJ12: 23668 | BK12: 11891 | BL12: 3480 | BM12: 4930 | BN12: 1741 | BO12: 29000 | BP12: 1124
A13: 45303 | B13: =CHOOSE(C13, "JANUARY", "FEBRUARY", "MARCH", "APRIL", "MAY", "JUNE", "JULY", "AUGUST", "SEPTEMBER", "OCTOBER", "NOVEMBER", "DECEMBER") -> JANUARY | C13: =MONTH(Data!$A13) -> 1 | D13: 560 | E13: 575 | F13: 123 | G13: 348 | H13: 89 | I13: 149 | J13: 369 | K13: 57 | L13: 156 | M13: 27 | N13: 34 | O13: 24 | P13: 24 | Q13: 85 | R13: 36 | S13: 19 | T13: 29 | U13: 126 | V13: 63 | W13: 17 | X13: 40 | Y13: 5 | Z13: 33 | AA13: 51 | AB13: 17 | AC13: 17 | AD13: 11 | AE13: 5 | AF13: 0 | AG13: 17 | AH13: 11 | AI13: 17 | AJ13: 0 | AK13: 28 | AL13: 23 | AM13: 28 | AN13: 0 | AO13: 0 | AP13: 5 | AQ13: 17 | AR13: 40 | AS13: 17 | AT13: 51 | AU13: 11 | AV13: 0 | AW13: 11 | AX13: 17 | AY13: 23 | AZ13: 0 | BA13: 104.067 | BB13: 0 | BC13: 0 | BD13: 0 | BE13: 0 | BF13: 0 | BG13: 50000 | BH13: 10000 | BI13: 5000 | BJ13: 12386 | BK13: 11891 | BL13: 3480 | BM13: 4930 | BN13: 1741 | BO13: 29000 | BP13: 5206
... A367: 45657 | B367: =CHOOSE(C367, "JANUARY", "FEBRUARY", "MARCH", "APRIL", "MAY", "JUNE", "JULY", "AUGUST", "SEPTEMBER", "OCTOBER", "NOVEMBER", "DECEMBER") -> DECEMBER | C367: =MONTH(Data!$A367) -> 12 | D367: 1140 | E367: 881 | F367: 319 | G367: 628 | H367: 193 | I367: 308 | J367: 415 | K367: 158 | L367: 348 | M367: 226 | N367: 63 | O367: 84 | P367: 35 | Q367: 186 | R367: 95 | S367: 60 | T367: 43 | U367: 0 | V367: 35 | W367: 0 | X367: 26 | Y367: 0 | Z367: 61 | AA367: 79 | AB367: 0 | AC367: 17 | AD367: 44 | AE367: 0 | AF367: 8 | AG367: 26 | AH367: 0 | AI367: 17 | AJ367: 17 | AK367: 79 | AL367: 61 | AM367: 17 | AN367: 0 | AO367: 0 | AP367: 8 | AQ367: 26 | AR367: 61 | AS367: 26 | AT367: 35 | AU367: 17 | AV367: 8 | AW367: 61 | AX367: 35 | AY367: 26 | AZ367: 91 | BA367: 200.277 | BB367: 47336.27 | BC367: 41874.39 | BD367: 45515.64 | BE367: 45515.64 | BF367: 1820.63 | BG367: 8000 | BH367: 6250 | BI367: 3353 | BJ367: 7058 | BK367: 75603 | BL367: 63201 | BM367: 55501 | BN367: 30000 | BO367: 230000 | BP367: 8202

Sheet Resources
B1: Colors | C1: Position | D1: Angle | E1: Transparency | G1: Shadow | H1: 0.2 | I1: 100 | J1: 35 | K1: 135 | L1: 15 | O1: $#,##0;-$#,##0; | R1: [0>=1000]0,"k";[<=1000]-0,"k";0
B2: #12143D | G2: Shadow | H2: 0.2 | I2: 100 | J2: 35 | K2: 135 | L2: 8
B3: #1F2357 | C3: 0 | D3: 135 | G3: Shadow | H3: 0.2 | I3: 100 | J3: 15 | K3: 135 | L3: 15
B4: #10123B | C4: 75 | D4: 135
A5: Line | B5: #4647A6 | C5: 0 | D5: 135
A6: Line | B6: #333787 | C6: 100 | D6: 135
B8: #20245A | C8: 0 | D8: 135
B9: #10123B | C9: 75 | D9: 135
A10: Line | B10: #B9C1FF | C10: 0 | D10: 150
A11: Line | B11: #3D4098 | C11: 33 | D11: 150
A12: Line | B12: #333787 | C12: 100 | D12: 150
B14: #323687 | C14: 0 | D14: 110
B15: #10123A | C15: 75 | D15: 110
A16: Line | B16: #A2D8F0 | C16: 0 | D16: 135
A17: Line | B17: #5D63D1 | C17: 38 | D17: 135
A18: Line | B18: #2E327A | C18: 100 | D18: 135
B20: #CEC5FF
B21: #6372A4
B22: #0575F1
B24: #22255C | C24: 0 | D24: 0
B25: #2C3076 | C25: 5 | D25: 0
B26: #2C3076 | C26: 97 | D26: 0
B27: #323687 | C27: 100 | D27: 0
A28: Line | B28: #A2D8F0 | C28: 0 | D28: 135
A29: Line | B29: #5D63D1 | C29: 38 | D29: 135
A30: Line | B30: #2E327A | C30: 100 | D30: 135
B31: #2069F0
B32: #9933FF
B34: #22248D | C34: 10 | D34: 135
B35: #060839 | C35: 67 | D35: 135
A36: Line | B36: #7079FF | C36: 25 | D36: 135
A37: Line | B37: #1C1D86 | C37: 100 | D37: 135
B39: #374AEC
B40: #1B2399
B41: #7C93FD
B42: #4641D1
B43: #0093CE
B44: #FF00FF
B46: #808AEC | C46: 10 | D46: 90
B47: #4A59E4 | C47: 80 | D47: 90
...
